<?xml version="1.0" encoding="utf-8"?>
<!-- This URDF was automatically created by SolidWorks to URDF Exporter! Originally created by Stephen Brawner (brawner@gmail.com) Commit Version: 1.6.0-1-g15f4949 Build Version: 1.6.7594.29634 For more information, please see
http://wiki.ros.org/sw_urdf_exporter -->

<!--
┏━━━━━┓┏━━━━━━┳━┓    ┏━┓    ┏━┓  ┏━┓
┃ ┏━┓ ┃┃ ┏━━┓ ┃ ┃    ┃ ┃    ┃ ┃  ┃ ┃
┃ ┗━┛ ┗┫ ┃  ┃ ┃ ┃    ┃ ┃    ┃ ┃  ┃ ┃
┃ ┏━━┓ ┃ ┗━━┛ ┃ ┃  ┏━┫ ┃  ┏━┫ ┃  ┃ ┃
┃ ┗━━┛ ┃ ┏━━┓ ┃ ┗━━┛ ┃ ┗━━┛ ┃ ┗━━┛ ┃
┗━━━━━━┻━┛  ┗━┻━━━━━━┻━━━━━━┻━━━━━━┛

MODIFIED VERSION: Femur:Tibia ratio = 3:7
Original total leg length preserved: 74.986 cm
New femur length: 22.496 cm
New tibia length: 52.490 cm
-->

<robot name="ballu">
  <!-- ============================== -->
  <!--        LINK DEFINITIONS        -->
  <!-- ============================== -->
  <link name="base_link"></link>
  <link name="PELVIS">
    <inertial>
      <origin xyz="-0.00044 0.00002 -0.0039" rpy="0 0 0"/><mass value="0.02127"/><inertia ixx="2.394281E-05" iyy="2.165260E-06" izz="2.361908E-05" ixy="1.327084E-08" ixz="7.820202E-08" iyz="1.342177E-08"/>
    </inertial>
    <visual>
      <origin xyz="0 0 0" rpy="0 0 0"/>
      <geometry><mesh filename="package://urdf/meshes/PELVIS.STL"/></geometry>
      <material name="color_pelvis" />
    </visual>
    <collision>
      <origin xyz="0 0 0" rpy="1.57079632679 0 0"/>
      <geometry><cylinder radius="0.005" length="0.15"/></geometry>
    </collision>
  </link>


  <link name="FEMUR_LEFT">
    <inertial>
      <!-- Adjusted for shorter femur: mass scaled proportionally, COM adjusted -->
      <origin xyz="-0.00005 0.11065 0" rpy="0 0 0"/><mass value="0.00582"/><inertia ixx="3.787E-05" iyy="6.309E-08" izz="3.787E-05" ixy="-5.522E-08" ixz="0.000000E+00" iyz="3.402E-09"/>
    </inertial>
    <visual>
      <origin xyz="0 0 0" rpy="0 0 0"/>
      <geometry><mesh filename="package://urdf/meshes/FEMUR_LEFT.STL" scale="1.0 0.616 1.0"/></geometry>
      <material name="color_femur_left" />
    </visual>
    <collision>
      <origin xyz="0 0.11248 0" rpy="1.57079632679 0 0"/>
      <geometry><cylinder radius="0.005" length="0.22496"/></geometry>
    </collision>
  </link>
  <link name="FEMUR_RIGHT">
    <inertial>
      <!-- Adjusted for shorter femur: mass scaled proportionally, COM adjusted -->
      <origin xyz="-0.00005 0.11065 0" rpy="0 0 0"/><mass value="0.00582"/><inertia ixx="3.787E-05" iyy="6.309E-08" izz="3.787E-05" ixy="-5.522E-08" ixz="0.000000E+00" iyz="3.402E-09"/>
    </inertial>
    <visual>
      <origin xyz="0 0 0" rpy="0 0 0"/>
      <geometry><mesh filename="package://urdf/meshes/FEMUR_RIGHT.STL" scale="1.0 0.616 1.0"/></geometry>
      <material name="color_femur_right" />
    </visual>
    <collision>
      <origin xyz="0 0.11248 0" rpy="1.57079632679 0 0"/>
      <geometry><cylinder radius="0.005" length="0.22496"/></geometry>
    </collision>
  </link>


  <link name="TIBIA_LEFT">
    <inertial>
      <!-- Adjusted for longer tibia: mass scaled proportionally, COM adjusted -->
      <origin xyz="0.0068 0.30845 -0.00419" rpy="0 0 0"/><mass value="0.05953"/><inertia ixx="3.453E-04" iyy="7.709E-06" izz="3.526E-04" ixy="3.518E-06" ixz="3.513E-07" iyz="-3.471E-06"/>
    </inertial>
    <visual>
      <origin xyz="0 0 0" rpy="0 0 0"/>
      <geometry><mesh filename="package://urdf/meshes/TIBIA_LEFT.STL" scale="1.0 1.364 1.0"/></geometry>
      <material name="color_tibia_left" />
    </visual>
    <collision> <!-- TIBIA_LEFT -->
      <origin xyz="0 0.26245 0" rpy="1.57079632679 0 0"/>
      <geometry><cylinder radius="0.005" length="0.5249"/></geometry>
      <contact_coefficients mu="0.9" />
    </collision>
    <collision> <!-- FOOT_LEFT -->
      <origin xyz="0 0.5249 0" rpy="1.57079632679 0 0"/>
      <geometry><sphere radius="0.004" /></geometry>
      <contact_coefficients mu="0.9" />
    </collision>
  </link>
  <link name="TIBIA_RIGHT">
    <inertial>
      <!-- Adjusted for longer tibia: mass scaled proportionally, COM adjusted -->
      <origin xyz="0.0068 0.30845 -0.00419" rpy="0 0 0"/>
      <mass value="0.05953"/>
      <inertia ixx="3.453E-04" iyy="7.709E-06" izz="3.526E-04" ixy="3.518E-06" ixz="3.513E-07" iyz="-3.471E-06"/>
    </inertial>
    <visual>
      <origin xyz="0 0 0" rpy="0 0 0"/>
      <geometry><mesh filename="package://urdf/meshes/TIBIA_RIGHT.STL" scale="1.0 1.364 1.0"/></geometry>
      <material name="color_tibia_right" />
    </visual>
    <collision> <!-- TIBIA_RIGHT -->
      <origin xyz="0 0.26245 0" rpy="1.57079632679 0 0"/>
      <geometry><cylinder radius="0.005" length="0.5249"/></geometry>
      <contact_coefficients mu="0.9" />
    </collision>
    <collision> <!-- FOOT_RIGHT -->
      <origin xyz="0 0.5249 0" rpy="1.5707963267949 0 0"/>
      <geometry><sphere radius="0.004"/></geometry>
      <contact_coefficients mu="0.9" />
    </collision>
  </link>


  <link name="MOTORARM_LEFT">
    <inertial>
      <origin xyz="0.00168 0 -0.00063" rpy="0 0 0" /><mass value="0.00016" /><inertia ixx="4.000000E-10" iyy="1.600000E-09" izz="1.730000E-09" ixy="0.000000E+00" ixz="1.700000E-10" iyz="0.000000E+00" />
    </inertial>
    <visual>
      <origin xyz="0 0 0" rpy="0 0 0"/>
      <geometry><mesh filename="package://urdf/meshes/MOTORARM_LEFT.STL"/></geometry>
      <material name="color_motorarm" />
    </visual>
    <collision>
      <origin xyz="0 0 0" rpy="0 0 1.57079632679"/>
      <geometry><box size="0.004 0.012 0.002"/></geometry>
    </collision>
  </link>
  <link name="MOTORARM_RIGHT">
    <inertial>
      <origin xyz="0.00168 0 -0.00063" rpy="0 0 0" /><mass value="0.00016" />
      <inertia ixx="4.000000E-10" iyy="1.600000E-09" izz="1.730000E-09" ixy="0.000000E+00" ixz="1.700000E-10" iyz="0.000000E+00" />
    </inertial>
    <visual>
      <origin xyz="0 0 0" rpy="0 0 0"/>
      <geometry><mesh filename="package://urdf/meshes/MOTORARM_RIGHT.STL"/></geometry>
      <material name="color_motorarm" />
    </visual>
    <collision>
      <origin xyz="0 0 0" rpy="0 0 1.57079632679"/>
      <geometry><box size="0.004 0.012 0.002"/></geometry>
    </collision>
  </link>


  <link name="BALLOON">
    <inertial>
      <origin xyz="-0.00006 -0.37953 0" rpy="0 0 0"/>
      <mass value="0.15898"/>
      <inertia ixx="1.421434E-02" iyy="1.025578E-02" izz="1.420794E-02" ixy="-3.811700E-06" ixz="0.000000E+00" iyz="0.000000E+00"/>
    </inertial>
    <visual>
      <origin xyz="0 0 0" rpy="0 0 0"/>
      <geometry><mesh filename="package://urdf/meshes/BALLOON.STL"/></geometry>
      <material name="color_balloons" />
    </visual>
    <collision>
      <origin xyz="0 -0.38 0" rpy="1.57079632679 0 0"/>
      <geometry><cylinder radius="0.32" length="0.7"/></geometry>
    </collision>
  </link>


  <!-- ============================== -->
  <!--        JOINT DEFINITIONS       -->
  <!-- ============================== -->

  <!-- Kinematic Joints -->
  <joint name="HIP_LEFT" type="revolute">
    <origin xyz="0 0.058025 0" rpy="-1.57079632679 0 0"/>
    <parent link="PELVIS"/>
    <child link="FEMUR_LEFT"/>
    <axis xyz="0 0 1"/>
    <limit lower="-1.57079632679" upper="1.57079632679" effort="0" velocity="0"/>
    <dynamics damping="1e-2" friction="1e-2" />
  </joint>
  <joint name="HIP_RIGHT" type="revolute">
    <origin xyz="0 -0.058025 0" rpy="-1.57079632679 0 0"/>
    <parent link="PELVIS"/>
    <child link="FEMUR_RIGHT"/>
    <axis xyz="0 0 1"/>
    <limit lower="-1.57079632679" upper="1.57079632679" effort="0" velocity="0"/>
    <dynamics damping="1e-2" friction="1e-2" />
  </joint>

  <joint name="KNEE_LEFT" type="revolute">
    <!-- Updated knee position for shorter femur -->
    <origin xyz="0 0.22496 0" rpy="0 0 0"/>
    <parent link="FEMUR_LEFT"/>
    <child link="TIBIA_LEFT"/>
    <axis xyz="0 0 1"/>
    <limit lower="0" upper="1.7453292519943295" effort="0" velocity="0"/>
    <dynamics damping="1e-2" friction="1e-2" />
  </joint>
  <joint name="KNEE_RIGHT" type="revolute">
    <!-- Updated knee position for shorter femur -->
    <origin xyz="0 0.22496 0" rpy="0 0 0"/>
    <parent link="FEMUR_RIGHT"/>
    <child link="TIBIA_RIGHT"/>
    <axis xyz="0 0 1"/>
    <limit lower="0" upper="1.7453292519943295" effort="0" velocity="0"/>
    <dynamics damping="1e-2" friction="1e-2" />
  </joint>

  <joint name="MOTOR_LEFT" type="revolute">
    <!-- Updated motor position for longer tibia (scaled proportionally) -->
    <origin xyz="-0.008375 0.44661 0.001" rpy="-3.14159265359 0 -1.57079632679"/>
    <parent link="TIBIA_LEFT"/>
    <child link="MOTORARM_LEFT"/>
    <axis xyz="0 0 1"/>
    <limit lower="0" upper="3.14159265359" effort="0" velocity="0"/>
    <dynamics damping="0" friction="0" />
  </joint>
  <joint name="MOTOR_RIGHT" type="revolute">
    <!-- Updated motor position for longer tibia (scaled proportionally) -->
    <origin xyz="-0.008375 0.44661 -0.001" rpy="3.14159265359 0 -1.57079632679"/>
    <parent link="TIBIA_RIGHT"/>
    <child link="MOTORARM_RIGHT"/>
    <axis xyz="0 0 1"/>
    <limit lower="0" upper="3.14159265359" effort="0" velocity="0"/>
    <dynamics damping="0" friction="0" />
  </joint>

  <joint name="NECK" type="revolute">
    <origin xyz="0.0044439 0 0.015" rpy="-1.57079632679 0 0"/>
    <parent link="PELVIS"/>
    <child link="BALLOON"/>
    <axis xyz="0 0 1"/>
    <limit lower="-1.57079632679" upper="1.57079632679" effort="0" velocity="0"/>
    <dynamics damping="0" friction="0" />
  </joint>


  <!-- Link Colors -->
  <material name="color_pelvis"><color rgba="0 0.8 0 1"/></material>
  <material name="color_femur_left"><color rgba="0.8 0 0 1"/></material>
  <material name="color_femur_right"><color rgba="0 0 0.8 1"/></material>
  <material name="color_tibia_left"><color rgba="0.75 0.3 0.3 1"/></material>
  <material name="color_tibia_right"><color rgba="0.3 0.3 0.75 1"/></material>
  <material name="color_motorarm"><color rgba="1 0.93725 0.13725 1"/></material>
  <material name="color_balloons"><color rgba="0.7 0.7 0.7 0.7"/></material>
</robot>


<!-- pi = 3.14159265359, pi/2=1.57079632679, pi/3=1.0471975512, pi/4=0.78539816339, pi/6=0.52359877559 --> 