<?xml version='1.0' encoding='utf-8'?>
<!--
MODIFIED VERSION: Femur:Tibia ratio = 4.0:6.0
Original total leg length preserved: 0.74986 m
New femur length: 0.29994 m
New tibia length: 0.44992 m
Generated by BalluLegRatioModifier
-->


<robot name="ballu">
  
  
  
  <link name="base_link" />
  <link name="PELVIS">
    <inertial>
      <origin xyz="-0.00044 0.00002 -0.0039" rpy="0 0 0" /><mass value="0.02127" /><inertia ixx="2.394281E-05" iyy="2.165260E-06" izz="2.361908E-05" ixy="1.327084E-08" ixz="7.820202E-08" iyz="1.342177E-08" />
    </inertial>
    <visual>
      <origin xyz="0 0 0" rpy="0 0 0" />
      <geometry><mesh filename="package://urdf/meshes/PELVIS.STL" /></geometry>
      <material name="color_pelvis" />
    </visual>
    <collision>
      <origin xyz="0 0 0" rpy="1.57079632679 0 0" />
      <geometry><cylinder radius="0.005" length="0.15" /></geometry>
    </collision>
  </link>


  <link name="FEMUR_LEFT">
    <inertial>
      <origin xyz="-0.00005 0.14755 0.00000" rpy="0 0 0" /><mass value="0.00776" /><inertia ixx="9.461077e-05" iyy="8.416921e-08" izz="9.460344e-05" ixy="-4.974834e-08" ixz="0.000000e+00" iyz="3.063826e-09" />
      
    </inertial>
    <visual>
      <origin xyz="0 0 0" rpy="0 0 0" />
      <geometry><mesh filename="package://urdf/meshes/FEMUR_LEFT.STL" scale="1.0 0.821742 1.0" /></geometry>
      <material name="color_femur_left" />
    </visual>
    <collision>
      <origin xyz="0 0.14997 0" rpy="1.57079632679 0 0" />
      <geometry><cylinder radius="0.005" length="0.29994" /></geometry>
    </collision>
  </link>
  <link name="FEMUR_RIGHT">
    <inertial>
      <origin xyz="-0.00005 0.14755 0.00000" rpy="0 0 0" /><mass value="0.00776" /><inertia ixx="9.461077e-05" iyy="8.416921e-08" izz="9.460344e-05" ixy="-4.974834e-08" ixz="0.000000e+00" iyz="3.063826e-09" />
      
    </inertial>
    <visual>
      <origin xyz="0 0 0" rpy="0 0 0" />
      <geometry><mesh filename="package://urdf/meshes/FEMUR_RIGHT.STL" scale="1.0 0.821742 1.0" /></geometry>
      <material name="color_femur_right" />
    </visual>
    <collision>
      <origin xyz="0 0.14997 0" rpy="1.57079632679 0 0" />
      <geometry><cylinder radius="0.005" length="0.29994" /></geometry>
    </collision>
  </link>


  <link name="TIBIA_LEFT">
    <inertial>
      <origin xyz="0.00680 0.26427 -0.00419" rpy="0 0 0" /><mass value="0.05105" /><inertia ixx="2.483864e-04" iyy="6.609371e-06" izz="2.539196e-04" ixy="4.124520e-06" ixz="4.117629e-07" iyz="-4.067598e-06" />
      
    </inertial>
    <visual>
      <origin xyz="0 0 0" rpy="0 0 0" />
      <geometry><mesh filename="package://urdf/meshes/TIBIA_LEFT.STL" scale="1.0 1.169068 1.0" /></geometry>
      <material name="color_tibia_left" />
    </visual>
    <collision> 
      <origin xyz="0 0.22496 0" rpy="1.57079632679 0 0" />
      <geometry><cylinder radius="0.005" length="0.44992" /></geometry>
      <contact_coefficients mu="0.9" />
    </collision>
    <collision> 
      <origin xyz="0 0.44992 0" rpy="1.57079632679 0 0" /> 
      <geometry><sphere radius="0.004" /></geometry>
      <contact_coefficients mu="0.9" />
    </collision>
  </link>
  <link name="TIBIA_RIGHT">
    <inertial>
      
      <origin xyz="0.00680 0.26427 -0.00419" rpy="0 0 0" />
      <mass value="0.05105" />
      <inertia ixx="2.483864e-04" iyy="6.609371e-06" izz="2.539196e-04" ixy="4.124520e-06" ixz="4.117629e-07" iyz="-4.067598e-06" />
      
    </inertial>
    <visual>
      <origin xyz="0 0 0" rpy="0 0 0" />
      <geometry><mesh filename="package://urdf/meshes/TIBIA_RIGHT.STL" scale="1.0 1.169068 1.0" /></geometry>
      <material name="color_tibia_right" />
    </visual>
    <collision> 
      <origin xyz="0 0.22496 0" rpy="1.57079632679 0 0" />
      <geometry><cylinder radius="0.005" length="0.44992" /></geometry>
      <contact_coefficients mu="0.9" />
    </collision>
    <collision> 
      <origin xyz="0 0.44992 0" rpy="1.5707963267949 0 0" /> 
      <geometry><sphere radius="0.004" /></geometry>
      <contact_coefficients mu="0.9" />
    </collision>
  </link>


  <link name="MOTORARM_LEFT">
    <inertial>
      <origin xyz="0.00168 0 -0.00063" rpy="0 0 0" /><mass value="0.00016" /><inertia ixx="4.000000E-10" iyy="1.600000E-09" izz="1.730000E-09" ixy="0.000000E+00" ixz="1.700000E-10" iyz="0.000000E+00" />
    </inertial>
    <visual>
      <origin xyz="0 0 0" rpy="0 0 0" />
      <geometry><mesh filename="package://urdf/meshes/MOTORARM_LEFT.STL" /></geometry>
      <material name="color_motorarm" />
    </visual>
    <collision>
      <origin xyz="0 0 0" rpy="0 0 1.57079632679" />
      <geometry><box size="0.004 0.012 0.002" /></geometry>
    </collision>
  </link>
  <link name="MOTORARM_RIGHT">
    <inertial>
      <origin xyz="0.00168 0 -0.00063" rpy="0 0 0" /><mass value="0.00016" />
      <inertia ixx="4.000000E-10" iyy="1.600000E-09" izz="1.730000E-09" ixy="0.000000E+00" ixz="1.700000E-10" iyz="0.000000E+00" />
      
    </inertial>
    <visual>
      <origin xyz="0 0 0" rpy="0 0 0" />
      <geometry><mesh filename="package://urdf/meshes/MOTORARM_RIGHT.STL" /></geometry>
      <material name="color_motorarm" />
    </visual>
    <collision>
      <origin xyz="0 0 0" rpy="0 0 1.57079632679" />
      <geometry><box size="0.004 0.012 0.002" /></geometry>
    </collision>
  </link>


  <link name="BALLOON">
    <inertial>
      <origin xyz="-0.00006 -0.37953 0" rpy="0 0 0" />
      <mass value="0.15898" />
      <inertia ixx="1.421434E-02" iyy="1.025578E-02" izz="1.420794E-02" ixy="-3.811700E-06" ixz="0.000000E+00" iyz="0.000000E+00" />
    </inertial>
    <visual>
      <origin xyz="0 0 0" rpy="0 0 0" />
      <geometry><mesh filename="package://urdf/meshes/BALLOON.STL" /></geometry>
      <material name="color_balloons" />
    </visual>
    <collision>
      <origin xyz="0 -0.38 0" rpy="1.57079632679 0 0" />
      <geometry><cylinder radius="0.32" length="0.7" /></geometry>
    </collision>
  </link>


  
  
  

  
  <joint name="HIP_LEFT" type="revolute">
    <origin xyz="0 0.058025 0" rpy="-1.57079632679 0 0" />
    <parent link="PELVIS" />
    <child link="FEMUR_LEFT" />
    <axis xyz="0 0 1" />
    <limit lower="-1.57079632679" upper="1.57079632679" effort="0" velocity="0" />
    <dynamics damping="1e-2" friction="1e-2" />
  </joint>
  <joint name="HIP_RIGHT" type="revolute">
    <origin xyz="0 -0.058025 0" rpy="-1.57079632679 0 0" />
    <parent link="PELVIS" />
    <child link="FEMUR_RIGHT" />
    <axis xyz="0 0 1" />
    <limit lower="-1.57079632679" upper="1.57079632679" effort="0" velocity="0" />
    <dynamics damping="1e-2" friction="1e-2" />
  </joint>

  <joint name="KNEE_LEFT" type="revolute">
    <origin xyz="0 0.29994 0" rpy="0 0 0" />
    <parent link="FEMUR_LEFT" />
    <child link="TIBIA_LEFT" />
    <axis xyz="0 0 1" />
    
    <limit lower="0" upper="1.7453292519943295" effort="0" velocity="0" />
    <dynamics damping="1e-2" friction="1e-2" />
  </joint>
  <joint name="KNEE_RIGHT" type="revolute">
    <origin xyz="0 0.29994 0" rpy="0 0 0" />
    <parent link="FEMUR_RIGHT" />
    <child link="TIBIA_RIGHT" />
    <axis xyz="0 0 1" />
    
    <limit lower="0" upper="1.7453292519943295" effort="0" velocity="0" />
    <dynamics damping="1e-2" friction="1e-2" />
  </joint>

  <joint name="MOTOR_LEFT" type="revolute">
    <origin xyz="-0.008375 0.38266 0.001" rpy="-3.14159265359 0 -1.57079632679" />
    <parent link="TIBIA_LEFT" />
    <child link="MOTORARM_LEFT" />
    <axis xyz="0 0 1" />
    <limit lower="0" upper="3.14159265359" effort="0" velocity="0" />
    <dynamics damping="0" friction="0" />
  </joint>
  <joint name="MOTOR_RIGHT" type="revolute">
    <origin xyz="-0.008375 0.38266 -0.001" rpy="3.14159265359 0 -1.57079632679" />
    <parent link="TIBIA_RIGHT" />
    <child link="MOTORARM_RIGHT" />
    <axis xyz="0 0 1" />
    <limit lower="0" upper="3.14159265359" effort="0" velocity="0" />
    <dynamics damping="0" friction="0" />
  </joint>

  <joint name="NECK" type="revolute">
    <origin xyz="0.0044439 0 0.015" rpy="-1.57079632679 0 0" />
    <parent link="PELVIS" />
    <child link="BALLOON" />
    <axis xyz="0 0 1" />
    <limit lower="-1.57079632679" upper="1.57079632679" effort="0" velocity="0" />
    <dynamics damping="0" friction="0" />
  </joint>


  
  <material name="color_pelvis"><color rgba="0 0.8 0 1" /></material>
  <material name="color_femur_left"><color rgba="0.8 0 0 1" /></material>
  <material name="color_femur_right"><color rgba="0 0 0.8 1" /></material>
  <material name="color_tibia_left"><color rgba="0.75 0.3 0.3 1" /></material>
  <material name="color_tibia_right"><color rgba="0.3 0.3 0.75 1" /></material>
  <material name="color_motorarm"><color rgba="1 0.93725 0.13725 1" /></material>
  <material name="color_balloons"><color rgba="0.7 0.7 0.7 0.7" /></material>
</robot>